<?xml version="1.0" encoding="utf-8"?>
<robot name="dual_arm_with_omnipicker">
  <!-- World link -->
  <link name="world"/>

  <!-- ========== 左臂 (Left Arm) ========== -->
  <link name="left_base_link">
    <inertial>
      <origin xyz="-3.493E-05 1.9321E-08 0.041738" rpy="0 0 0" />
      <mass value="1.235" />
      <inertia
        ixx="0.00069305"
        ixy="-2.4629E-09"
        ixz="-7.7538E-07"
        iyy="0.00069224"
        iyz="1.1986E-09"
        izz="0.00059207" />
    </inertial>
    <visual>
      <origin xyz="0 0 0" rpy="0 0 0" />
      <geometry>
        <mesh filename="package://robot_description/meshes/arm620/base_link.STL" />
      </geometry>
      <material name="">
        <color rgba="0.5 0.5 1 1" />
      </material>
    </visual>
    <collision>
      <origin xyz="0 0 0" rpy="0 0 0" />
      <geometry>
        <mesh filename="package://robot_description/meshes/arm620/base_link.STL" />
      </geometry>
    </collision>
  </link>

  <link name="left_Link1">
    <inertial>
      <origin xyz="0.0083082 -9.0414E-07 0.066279" rpy="0 0 0" />
      <mass value="1.0225" />
      <inertia
        ixx="0.00033468"
        ixy="-1.0629E-08"
        ixz="-6.9769E-06"
        iyy="0.0002898"
        iyz="-1.0465E-08"
        izz="0.00026359" />
    </inertial>
    <visual>
      <origin xyz="0 0 0" rpy="0 0 0" />
      <geometry>
        <mesh filename="package://robot_description/meshes/arm620/Link1.STL" />
      </geometry>
      <material name="">
        <color rgba="0.5 0.5 1 1" />
      </material>
    </visual>
    <collision>
      <origin xyz="0 0 0" rpy="0 0 0" />
      <geometry>
        <mesh filename="package://robot_description/meshes/arm620/Link1.STL" />
      </geometry>
    </collision>
  </link>

  <link name="left_Link2">
    <inertial>
      <origin xyz="1.6176E-06 0.19554 -0.0019139" rpy="0 0 0" />
      <mass value="1.925" />
      <inertia
        ixx="0.0092613"
        ixy="2.9244E-08"
        ixz="-6.7107E-09"
        iyy="0.00075528"
        iyz="-1.5539E-05"
        izz="0.0090845" />
    </inertial>
    <visual>
      <origin xyz="0 0 0" rpy="0 0 0" />
      <geometry>
        <mesh filename="package://robot_description/meshes/arm620/Link2.STL" />
      </geometry>
      <material name="">
        <color rgba="0.5 0.5 1 1" />
      </material>
    </visual>
    <collision>
      <origin xyz="0 0 0" rpy="0 0 0" />
      <geometry>
        <mesh filename="package://robot_description/meshes/arm620/Link2.STL" />
      </geometry>
    </collision>
  </link>

  <link name="left_Link3">
    <inertial>
      <origin xyz="1.8251E-05 -0.073691 0.010704" rpy="0 0 0" />
      <mass value="0.73" />
      <inertia
        ixx="0.00059318"
        ixy="1.2073E-07"
        ixz="1.9423E-08"
        iyy="0.00015563"
        iyz="-0.00011324"
        izz="0.00055379" />
    </inertial>
    <visual>
      <origin xyz="0 0 0" rpy="0 0 0" />
      <geometry>
        <mesh filename="package://robot_description/meshes/arm620/Link3.STL" />
      </geometry>
      <material name="">
        <color rgba="0.5 0.5 1 1" />
      </material>
    </visual>
    <collision>
      <origin xyz="0 0 0" rpy="0 0 0" />
      <geometry>
        <mesh filename="package://robot_description/meshes/arm620/Link3.STL" />
      </geometry>
    </collision>
  </link>

  <link name="left_Link4">
    <inertial>
      <origin xyz="0.0059454 2.5068E-05 0.051809" rpy="0 0 0" />
      <mass value="0.5174" />
      <inertia
        ixx="0.00010342"
        ixy="-7.9433E-09"
        ixz="-7.9245E-06"
        iyy="0.0001193"
        iyz="-1.6196E-08"
        izz="8.5637E-05" />
    </inertial>
    <visual>
      <origin xyz="0 0 0" rpy="0 0 0" />
      <geometry>
        <mesh filename="package://robot_description/meshes/arm620/Link4.STL" />
      </geometry>
      <material name="">
        <color rgba="0.5 0.5 1 1" />
      </material>
    </visual>
    <collision>
      <origin xyz="0 0 0" rpy="0 0 0" />
      <geometry>
        <mesh filename="package://robot_description/meshes/arm620/Link4.STL" />
      </geometry>
    </collision>
  </link>

  <link name="left_Link5">
    <inertial>
      <origin xyz="0.0095168 0.061153 1.0106E-05" rpy="0 0 0" />
      <mass value="0.7233" />
      <inertia
        ixx="0.00013586"
        ixy="3.9115E-05"
        ixz="3.3963E-08"
        iyy="0.00010055"
        iyz="-1.3885E-07"
        izz="0.0001594" />
    </inertial>
    <visual>
      <origin xyz="0 0 0" rpy="0 0 0" />
      <geometry>
        <mesh filename="package://robot_description/meshes/arm620/Link5.STL" />
      </geometry>
      <material name="">
        <color rgba="0.5 0.5 1 1" />
      </material>
    </visual>
    <collision>
      <origin xyz="0 0 0" rpy="0 0 0" />
      <geometry>
        <mesh filename="package://robot_description/meshes/arm620/Link5.STL" />
      </geometry>
    </collision>
  </link>

  <link name="left_Link6">
    <inertial>
      <origin xyz="-0.0023023 0.0016027 0.010682" rpy="0 0 0" />
      <mass value="0.0953" />
      <inertia
        ixx="1.3179E-05"
        ixy="-9.4826E-08"
        ixz="2.2437E-07"
        iyy="1.3416E-05"
        iyz="-1.8512E-07"
        izz="2.4622E-05" />
    </inertial>
    <visual>
      <origin xyz="0 0 0" rpy="0 0 0" />
      <geometry>
        <mesh filename="package://robot_description/meshes/arm620/Link6.STL" />
      </geometry>
      <material name="">
        <color rgba="0.5 0.5 1 1" />
      </material>
    </visual>
    <collision>
      <origin xyz="0 0 0" rpy="0 0 0" />
      <geometry>
        <mesh filename="package://robot_description/meshes/arm620/Link6.STL" />
      </geometry>
    </collision>
  </link>

  <!-- 左臂关节连接 -->
  <joint name="left_base_joint" type="fixed">
    <parent link="world"/>
    <child link="left_base_link"/>
    <origin xyz="0 -0.5 0" rpy="0 0 0" />
    <axis xyz="0 0 1" />
  </joint>

  <joint name="left_joint1" type="revolute">
    <origin xyz="0 0 0.084" rpy="0 0 0" />
    <parent link="left_base_link" />
    <child link="left_Link1" />
    <axis xyz="0 0 1" />
    <limit lower="-2.967" upper="2.967" effort="51" velocity="3.14" />
  </joint>

  <joint name="left_joint2" type="revolute">
    <origin xyz="0 0 0.068718" rpy="1.5708 0 -1.5708" />
    <parent link="left_Link1" />
    <child link="left_Link2" />
    <axis xyz="0 0 -1" />
    <limit lower="-1.5708" upper="1.5708" effort="51" velocity="3.14" />
  </joint>

  <joint name="left_joint3" type="revolute">
    <origin xyz="0 0.30025 0" rpy="-3.1416 0 0" />
    <parent link="left_Link2" />
    <child link="left_Link3" />
    <axis xyz="0 0 1" />
    <limit lower="-1.5708" upper="1.5708" effort="51" velocity="3.14" />
  </joint>

  <joint name="left_joint4" type="revolute">
    <origin xyz="0 -0.15558 3.5E-05" rpy="1.5708 -1.5708 0" />
    <parent link="left_Link3" />
    <child link="left_Link4" />
    <axis xyz="0 0 1" />
    <limit lower="-2.967" upper="2.967" effort="9" velocity="3.14" />
  </joint>

  <joint name="left_joint5" type="revolute">
    <origin xyz="-3.5E-05 1.5362E-05 0.064223" rpy="1.5708 0 0" />
    <parent link="left_Link4" />
    <child link="left_Link5" />
    <axis xyz="1 0 0" />
    <limit lower="-1.5708" upper="1.5708" effort="9" velocity="3.14" />
  </joint>

  <joint name="left_joint6" type="revolute">
    <origin xyz="-0.00047523 0.095552 0" rpy="-1.5709 0 0" />
    <parent link="left_Link5" />
    <child link="left_Link6" />
    <axis xyz="0 0 1" />
    <limit lower="-2.967" upper="2.967" effort="9" velocity="3.14" />
  </joint>

  <!-- ========== 左臂夹爪 (Left OmniPicker Gripper) ========== -->
  <joint name="left_gripper_base_joint" type="fixed">
    <origin xyz="0 0 0.022" rpy="0 0 1.5708" />
    <parent link="left_Link6" />
    <child link="left_gripper_base" />
    <axis xyz="0 0 1" />
  </joint>
  <link name="left_gripper_base">
    <inertial>
      <origin xyz="-0.00005520 1.2341E-05 0.03296193" rpy="0 0 0" />
      <mass value="0.25641368" />
      <inertia ixx="4.6351E-04" ixy="-1.0E-08" ixz="-1.04E-06" iyy="4.4525E-04" iyz="-5.00E-08" izz="1.0438E-04" />
    </inertial>
    <visual>
      <origin rpy="0 0 0" xyz="0 0 0" />
      <geometry>
        <mesh filename="package://robot_description/meshes/omnipicker_gripper/base_link.STL" />
      </geometry>
      <material name="">
        <color rgba="0.89804 0.91765 0.92941 1" />
      </material>
    </visual>
    <collision>
      <origin rpy="0 0 0" xyz="0 0 0" />
      <geometry>
        <mesh filename="package://robot_description/meshes/omnipicker_gripper/base_link.STL" />
      </geometry>
    </collision>
  </link>

  <link name="left_hand_narrow1_Link">
    <inertial>
      <origin xyz="0.0094685 0.0068806 6.5437E-05" rpy="0 0 0" />
      <mass value="0.025428" />
      <inertia ixx="1.9574E-06" ixy="-4.2911E-07" ixz="-3.7111E-11" iyy="2.3919E-06" iyz="-3.008E-10" izz="1.5501E-06" />
    </inertial>
    <visual>
      <origin xyz="0 0 0" rpy="0 0 0" />
      <geometry>
        <mesh filename="package://robot_description/meshes/omnipicker_gripper/narrow1_Link.STL" />
      </geometry>
      <material name="">
        <color rgba="0.75294 0.75294 0.75294 1" />
      </material>
    </visual>
    <collision>
      <origin xyz="0 0 0" rpy="0 0 0" />
      <geometry>
        <mesh filename="package://robot_description/meshes/omnipicker_gripper/narrow1_Link.STL" />
      </geometry>
    </collision>
  </link>

  <joint name="left_hand_narrow1_joint" type="revolute">
    <origin xyz="0 -0.0195 0.0565" rpy="-2.9951 -1.5708 -0.15964" />
    <parent link="left_gripper_base" />
    <child link="left_hand_narrow1_Link" />
    <axis xyz="0 0 -1" />
    <limit lower="-3.14" upper="3.14" effort="5" velocity="3.14" />
  </joint>

  <link name="left_hand_narrow2_Link">
    <inertial>
      <origin xyz="0.0088027 -0.007035 1.6424E-05" rpy="0 0 0" />
      <mass value="0.0040132" />
      <inertia ixx="1.0307E-07" ixy="5.7851E-08" ixz="9.5801E-11" iyy="1.1385E-07" iyz="-2.81E-11" izz="1.7009E-07" />
    </inertial>
    <visual>
      <origin xyz="0 0 0" rpy="0 0 0" />
      <geometry>
        <mesh filename="package://robot_description/meshes/omnipicker_gripper/narrow2_Link.STL" />
      </geometry>
      <material name="">
        <color rgba="0.75294 0.75294 0.75294 1" />
      </material>
    </visual>
    <collision>
      <origin xyz="0 0 0" rpy="0 0 0" />
      <geometry>
        <mesh filename="package://robot_description/meshes/omnipicker_gripper/narrow2_Link.STL" />
      </geometry>
    </collision>
  </link>

  <joint name="left_hand_narrow2_joint" type="revolute">
    <origin xyz="0.030852 0.018551 0" rpy="0 0 0" />
    <parent link="left_hand_narrow1_Link" />
    <child link="left_hand_narrow2_Link" />
    <axis xyz="0 0 -1" />
    <limit lower="-3.14" upper="3.14" effort="5" velocity="3.14" />
  </joint>

  <link name="left_hand_narrow3_Link">
    <inertial>
      <origin xyz="0.012508 -0.0079729 9.4339E-05" rpy="0 0 0" />
      <mass value="0.018029" />
      <inertia ixx="1.1403E-06" ixy="5.5159E-07" ixz="-4.0096E-13" iyy="2.5704E-06" iyz="1.0951E-12" izz="2.3252E-06" />
    </inertial>
    <visual>
      <origin xyz="0 0 0" rpy="0 0 0" />
      <geometry>
        <mesh filename="package://robot_description/meshes/omnipicker_gripper/narrow3_Link.STL" />
      </geometry>
      <material name="">
        <color rgba="0.75294 0.75294 0.75294 1" />
      </material>
    </visual>
    <collision>
      <origin xyz="0 0 0" rpy="0 0 0" />
      <geometry>
        <mesh filename="package://robot_description/meshes/omnipicker_gripper/narrow3_Link.STL" />
      </geometry>
    </collision>
  </link>

  <joint name="left_hand_narrow3_joint" type="revolute">
    <origin xyz="0.018118 -0.01574 0" rpy="0 0 0" />
    <parent link="left_hand_narrow2_Link" />
    <child link="left_hand_narrow3_Link" />
    <axis xyz="0 0 -1" />
    <limit lower="-3.14" upper="3.14" effort="5" velocity="3.14" />
  </joint>

  <link name="left_hand_narrow4_Link" />

  <joint name="left_hand_narrow4_joint" type="fixed">
    <origin xyz="0 -0.0104 0" rpy="0 0 0" />
    <parent link="left_hand_narrow3_Link" />
    <child link="left_hand_narrow4_Link" />
    <axis xyz="0 0 1" />
    <limit lower="-3.14" upper="3.14" effort="5" velocity="3.14" />
  </joint>

  <link name="left_hand_narrow_loop_Link">
    <inertial>
      <origin xyz="0.014869 -0.0036066 0.00029307" rpy="0 0 0" />
      <mass value="0.022591" />
      <inertia ixx="4.3916E-06" ixy="1.114E-07" ixz="-4.9655E-12" iyy="4.737E-06" iyz="1.7121E-11" izz="6.0445E-07" />
    </inertial>
    <visual>
      <origin xyz="0 0 0" rpy="0 0 0" />
      <geometry>
        <mesh filename="package://robot_description/meshes/omnipicker_gripper/narrow_loop_Link.STL" />
      </geometry>
      <material name="">
        <color rgba="0.75294 0.75294 0.75294 1" />
      </material>
    </visual>
    <collision>
      <origin xyz="0 0 0" rpy="0 0 0" />
      <geometry>
        <mesh filename="package://robot_description/meshes/omnipicker_gripper/narrow_loop_Link.STL" />
      </geometry>
    </collision>
  </link>

  <joint name="left_hand_narrow_loop_joint" type="revolute">
    <origin xyz="0 -0.021633 0.07387" rpy="-2.9951 -1.5708 -0.15964" />
    <parent link="left_gripper_base" />
    <child link="left_hand_narrow_loop_Link" />
    <axis xyz="0 0 -1" />
    <limit lower="-3.14" upper="3.14" effort="5" velocity="3.14" />
  </joint>

  <link name="left_hand_wide1_Link">
    <inertial>
      <origin xyz="0.0095051 -0.0068479 6.8268E-05" rpy="0 0 0" />
      <mass value="0.025428" />
      <inertia ixx="1.9565E-06" ixy="4.2798E-07" ixz="2.3844E-10" iyy="2.3928E-06" iyz="-1.4454E-10" izz="1.5501E-06" />
    </inertial>
    <visual>
      <origin xyz="0 0 0" rpy="0 0 0" />
      <geometry>
        <mesh filename="package://robot_description/meshes/omnipicker_gripper/wide1_Link.STL" />
      </geometry>
      <material name="">
        <color rgba="0.75294 0.75294 0.75294 1" />
      </material>
    </visual>
    <collision>
      <origin xyz="0 0 0" rpy="0 0 0" />
      <geometry>
        <mesh filename="package://robot_description/meshes/omnipicker_gripper/wide1_Link.STL" />
      </geometry>
    </collision>
  </link>

  <joint name="left_hand_wide1_joint" type="revolute">
    <origin xyz="0 0.0195 0.0565" rpy="-2.9951 -1.5708 -0.15964" />
    <parent link="left_gripper_base" />
    <child link="left_hand_wide1_Link" />
    <axis xyz="0 0 -1" />
    <limit lower="-3.14" upper="3.14" effort="5" velocity="3.14" />
  </joint>

  <link name="left_hand_wide2_Link">
    <inertial>
      <origin xyz="0.0088027 0.007035 -1.6424E-05" rpy="0 0 0" />
      <mass value="0.0040132" />
      <inertia ixx="1.0307E-07" ixy="-5.7851E-08" ixz="-9.58E-11" iyy="1.1385E-07" iyz="-2.81E-11" izz="1.7009E-07" />
    </inertial>
    <visual>
      <origin xyz="0 0 0" rpy="0 0 0" />
      <geometry>
        <mesh filename="package://robot_description/meshes/omnipicker_gripper/wide2_Link.STL" />
      </geometry>
      <material name="">
        <color rgba="0.75294 0.75294 0.75294 1" />
      </material>
    </visual>
    <collision>
      <origin xyz="0 0 0" rpy="0 0 0" />
      <geometry>
        <mesh filename="package://robot_description/meshes/omnipicker_gripper/wide2_Link.STL" />
      </geometry>
    </collision>
  </link>

  <joint name="left_hand_wide2_joint" type="revolute">
    <origin xyz="0.030852 -0.018551 0" rpy="0 0 0" />
    <parent link="left_hand_wide1_Link" />
    <child link="left_hand_wide2_Link" />
    <axis xyz="0 0 -1" />
    <limit lower="-3.14" upper="3.14" effort="5" velocity="3.14" />
  </joint>

  <link name="left_hand_wide3_Link">
    <inertial>
      <origin xyz="0.016206 0.0094593 4.7668E-05" rpy="0 0 0" />
      <mass value="0.035835" />
      <inertia ixx="8.5056E-06" ixy="-1.1363E-06" ixz="-4.2908E-11" iyy="1.1235E-05" iyz="-2.9251E-11" izz="4.6309E-06" />
    </inertial>
    <visual>
      <origin xyz="0 0 0" rpy="0 0 0" />
      <geometry>
        <mesh filename="package://robot_description/meshes/omnipicker_gripper/wide3_Link.STL" />
      </geometry>
      <material name="">
        <color rgba="0.75294 0.75294 0.75294 1" />
      </material>
    </visual>
    <collision>
      <origin xyz="0 0 0" rpy="0 0 0" />
      <geometry>
        <mesh filename="package://robot_description/meshes/omnipicker_gripper/wide3_Link.STL" />
      </geometry>
    </collision>
  </link>

  <joint name="left_hand_wide3_joint" type="revolute">
    <origin xyz="0.018118 0.01574 0" rpy="0 0 0" />
    <parent link="left_hand_wide2_Link" />
    <child link="left_hand_wide3_Link" />
    <axis xyz="0 0 -1" />
    <limit lower="-3.14" upper="3.14" effort="5" velocity="3.14" />
  </joint>

  <link name="left_hand_wide4_Link" />

  <joint name="left_hand_wide4_joint" type="fixed">
    <origin xyz="0 0.0104 0" rpy="0 0 0" />
    <parent link="left_hand_wide3_Link" />
    <child link="left_hand_wide4_Link" />
    <axis xyz="0 0 1" />
    <limit lower="-3.14" upper="3.14" effort="5" velocity="3.14" />
  </joint>

  <link name="left_hand_wide_loop_Link">
    <inertial>
      <origin xyz="0.016268 0.0040555 0.00030323" rpy="0 0 0" />
      <mass value="0.025142" />
      <inertia ixx="5.887E-06" ixy="-1.1234E-07" ixz="2.1954E-11" iyy="6.236E-06" iyz="-9.473E-12" izz="6.2389E-07" />
    </inertial>
    <visual>
      <origin xyz="0 0 0" rpy="0 0 0" />
      <geometry>
        <mesh filename="package://robot_description/meshes/omnipicker_gripper/wide_loop_Link.STL" />
      </geometry>
      <material name="">
        <color rgba="0.75294 0.75294 0.75294 1" />
      </material>
    </visual>
    <collision>
      <origin xyz="0 0 0" rpy="0 0 0" />
      <geometry>
        <mesh filename="package://robot_description/meshes/omnipicker_gripper/wide_loop_Link.STL" />
      </geometry>
    </collision>
  </link>

  <joint name="left_hand_wide_loop_joint" type="revolute">
    <origin xyz="0 0.021633 0.07387" rpy="-2.9951 -1.5708 -0.15964" />
    <parent link="left_gripper_base" />
    <child link="left_hand_wide_loop_Link" />
    <axis xyz="0 0 -1" />
    <limit lower="-3.14" upper="3.14" effort="5" velocity="3.14" />
  </joint>
  <!-- ========== 右臂 (Right Arm) ========== -->
  <link name="right_base_link">
    <inertial>
      <origin xyz="-3.493E-05 1.9321E-08 0.041738" rpy="0 0 0" />
      <mass value="1.235" />
      <inertia
        ixx="0.00069305"
        ixy="-2.4629E-09"
        ixz="-7.7538E-07"
        iyy="0.00069224"
        iyz="1.1986E-09"
        izz="0.00059207" />
    </inertial>
    <visual>
      <origin xyz="0 0 0" rpy="0 0 0" />
      <geometry>
        <mesh filename="package://robot_description/meshes/arm620/base_link.STL" />
      </geometry>
      <material name="">
        <color rgba="1 0.5 0.5 1" />
      </material>
    </visual>
    <collision>
      <origin xyz="0 0 0" rpy="0 0 0" />
      <geometry>
        <mesh filename="package://robot_description/meshes/arm620/base_link.STL" />
      </geometry>
    </collision>
  </link>

  <link name="right_Link1">
    <inertial>
      <origin xyz="0.0083082 -9.0414E-07 0.066279" rpy="0 0 0" />
      <mass value="1.0225" />
      <inertia
        ixx="0.00033468"
        ixy="-1.0629E-08"
        ixz="-6.9769E-06"
        iyy="0.0002898"
        iyz="-1.0465E-08"
        izz="0.00026359" />
    </inertial>
    <visual>
      <origin xyz="0 0 0" rpy="0 0 0" />
      <geometry>
        <mesh filename="package://robot_description/meshes/arm620/Link1.STL" />
      </geometry>
      <material name="">
        <color rgba="1 0.5 0.5 1" />
      </material>
    </visual>
    <collision>
      <origin xyz="0 0 0" rpy="0 0 0" />
      <geometry>
        <mesh filename="package://robot_description/meshes/arm620/Link1.STL" />
      </geometry>
    </collision>
  </link>

  <link name="right_Link2">
    <inertial>
      <origin xyz="1.6176E-06 0.19554 -0.0019139" rpy="0 0 0" />
      <mass value="1.925" />
      <inertia
        ixx="0.0092613"
        ixy="2.9244E-08"
        ixz="-6.7107E-09"
        iyy="0.00075528"
        iyz="-1.5539E-05"
        izz="0.0090845" />
    </inertial>
    <visual>
      <origin xyz="0 0 0" rpy="0 0 0" />
      <geometry>
        <mesh filename="package://robot_description/meshes/arm620/Link2.STL" />
      </geometry>
      <material name="">
        <color rgba="1 0.5 0.5 1" />
      </material>
    </visual>
    <collision>
      <origin xyz="0 0 0" rpy="0 0 0" />
      <geometry>
        <mesh filename="package://robot_description/meshes/arm620/Link2.STL" />
      </geometry>
    </collision>
  </link>

  <link name="right_Link3">
    <inertial>
      <origin xyz="1.8251E-05 -0.073691 0.010704" rpy="0 0 0" />
      <mass value="0.73" />
      <inertia
        ixx="0.00059318"
        ixy="1.2073E-07"
        ixz="1.9423E-08"
        iyy="0.00015563"
        iyz="-0.00011324"
        izz="0.00055379" />
    </inertial>
    <visual>
      <origin xyz="0 0 0" rpy="0 0 0" />
      <geometry>
        <mesh filename="package://robot_description/meshes/arm620/Link3.STL" />
      </geometry>
      <material name="">
        <color rgba="1 0.5 0.5 1" />
      </material>
    </visual>
    <collision>
      <origin xyz="0 0 0" rpy="0 0 0" />
      <geometry>
        <mesh filename="package://robot_description/meshes/arm620/Link3.STL" />
      </geometry>
    </collision>
  </link>

  <link name="right_Link4">
    <inertial>
      <origin xyz="0.0059454 2.5068E-05 0.051809" rpy="0 0 0" />
      <mass value="0.5174" />
      <inertia
        ixx="0.00010342"
        ixy="-7.9433E-09"
        ixz="-7.9245E-06"
        iyy="0.0001193"
        iyz="-1.6196E-08"
        izz="8.5637E-05" />
    </inertial>
    <visual>
      <origin xyz="0 0 0" rpy="0 0 0" />
      <geometry>
        <mesh filename="package://robot_description/meshes/arm620/Link4.STL" />
      </geometry>
      <material name="">
        <color rgba="1 0.5 0.5 1" />
      </material>
    </visual>
    <collision>
      <origin xyz="0 0 0" rpy="0 0 0" />
      <geometry>
        <mesh filename="package://robot_description/meshes/arm620/Link4.STL" />
      </geometry>
    </collision>
  </link>

  <link name="right_Link5">
    <inertial>
      <origin xyz="0.0095168 0.061153 1.0106E-05" rpy="0 0 0" />
      <mass value="0.7233" />
      <inertia
        ixx="0.00013586"
        ixy="3.9115E-05"
        ixz="3.3963E-08"
        iyy="0.00010055"
        iyz="-1.3885E-07"
        izz="0.0001594" />
    </inertial>
    <visual>
      <origin xyz="0 0 0" rpy="0 0 0" />
      <geometry>
        <mesh filename="package://robot_description/meshes/arm620/Link5.STL" />
      </geometry>
      <material name="">
        <color rgba="1 0.5 0.5 1" />
      </material>
    </visual>
    <collision>
      <origin xyz="0 0 0" rpy="0 0 0" />
      <geometry>
        <mesh filename="package://robot_description/meshes/arm620/Link5.STL" />
      </geometry>
    </collision>
  </link>

  <link name="right_Link6">
    <inertial>
      <origin xyz="-0.0023023 0.0016027 0.010682" rpy="0 0 0" />
      <mass value="0.0953" />
      <inertia
        ixx="1.3179E-05"
        ixy="-9.4826E-08"
        ixz="2.2437E-07"
        iyy="1.3416E-05"
        iyz="-1.8512E-07"
        izz="2.4622E-05" />
    </inertial>
    <visual>
      <origin xyz="0 0 0" rpy="0 0 0" />
      <geometry>
        <mesh filename="package://robot_description/meshes/arm620/Link6.STL" />
      </geometry>
      <material name="">
        <color rgba="1 0.5 0.5 1" />
      </material>
    </visual>
    <collision>
      <origin xyz="0 0 0" rpy="0 0 0" />
      <geometry>
        <mesh filename="package://robot_description/meshes/arm620/Link6.STL" />
      </geometry>
    </collision>
  </link>

  <!-- 右臂关节连接 -->
  <joint name="right_base_joint" type="fixed">
    <parent link="world"/>
    <child link="right_base_link"/>
    <origin xyz="0 0.5 0" rpy="0 0 0" />
    <axis xyz="0 0 1" />
  </joint>

  <joint name="right_joint1" type="revolute">
    <origin xyz="0 0 0.084" rpy="0 0 0" />
    <parent link="right_base_link" />
    <child link="right_Link1" />
    <axis xyz="0 0 1" />
    <limit lower="-2.967" upper="2.967" effort="51" velocity="3.14" />
  </joint>

  <joint name="right_joint2" type="revolute">
    <origin xyz="0 0 0.068718" rpy="1.5708 0 -1.5708" />
    <parent link="right_Link1" />
    <child link="right_Link2" />
    <axis xyz="0 0 -1" />
    <limit lower="-1.5708" upper="1.5708" effort="51" velocity="3.14" />
  </joint>

  <joint name="right_joint3" type="revolute">
    <origin xyz="0 0.30025 0" rpy="-3.1416 0 0" />
    <parent link="right_Link2" />
    <child link="right_Link3" />
    <axis xyz="0 0 1" />
    <limit lower="-1.5708" upper="1.5708" effort="51" velocity="3.14" />
  </joint>

  <joint name="right_joint4" type="revolute">
    <origin xyz="0 -0.15558 3.5E-05" rpy="1.5708 -1.5708 0" />
    <parent link="right_Link3" />
    <child link="right_Link4" />
    <axis xyz="0 0 1" />
    <limit lower="-2.967" upper="2.967" effort="9" velocity="3.14" />
  </joint>

  <joint name="right_joint5" type="revolute">
    <origin xyz="-3.5E-05 1.5362E-05 0.064223" rpy="1.5708 0 0" />
    <parent link="right_Link4" />
    <child link="right_Link5" />
    <axis xyz="1 0 0" />
    <limit lower="-1.5708" upper="1.5708" effort="9" velocity="3.14" />
  </joint>

  <joint name="right_joint6" type="revolute">
    <origin xyz="-0.00047523 0.095552 0" rpy="-1.5709 0 0" />
    <parent link="right_Link5" />
    <child link="right_Link6" />
    <axis xyz="0 0 1" />
    <limit lower="-2.967" upper="2.967" effort="9" velocity="3.14" />
  </joint>

  <!-- ========== 右臂夹爪 (Right OmniPicker Gripper) ========== -->
  <joint name="right_gripper_base_joint" type="fixed">
    <origin xyz="0 0 0.022" rpy="0 0 1.5708" />
    <parent link="right_Link6" />
    <child link="right_gripper_base" />
    <axis xyz="0 0 1" />
  </joint>
  <link name="right_gripper_base">
    <inertial>
      <origin xyz="-0.00005520 1.2341E-05 0.03296193" rpy="0 0 0" />
      <mass value="0.25641368" />
      <inertia ixx="4.6351E-04" ixy="-1.0E-08" ixz="-1.04E-06" iyy="4.4525E-04" iyz="-5.00E-08" izz="1.0438E-04" />
    </inertial>
    <visual>
      <origin rpy="0 0 0" xyz="0 0 0" />
      <geometry>
        <mesh filename="package://robot_description/meshes/omnipicker_gripper/base_link.STL" />
      </geometry>
      <material name="">
        <color rgba="0.89804 0.91765 0.92941 1" />
      </material>
    </visual>
    <collision>
      <origin rpy="0 0 0" xyz="0 0 0" />
      <geometry>
        <mesh filename="package://robot_description/meshes/omnipicker_gripper/base_link.STL" />
      </geometry>
    </collision>
  </link>

  <link name="right_hand_narrow1_Link">
    <inertial>
      <origin xyz="0.0094685 0.0068806 6.5437E-05" rpy="0 0 0" />
      <mass value="0.025428" />
      <inertia ixx="1.9574E-06" ixy="-4.2911E-07" ixz="-3.7111E-11" iyy="2.3919E-06" iyz="-3.008E-10" izz="1.5501E-06" />
    </inertial>
    <visual>
      <origin xyz="0 0 0" rpy="0 0 0" />
      <geometry>
        <mesh filename="package://robot_description/meshes/omnipicker_gripper/narrow1_Link.STL" />
      </geometry>
      <material name="">
        <color rgba="0.75294 0.75294 0.75294 1" />
      </material>
    </visual>
    <collision>
      <origin xyz="0 0 0" rpy="0 0 0" />
      <geometry>
        <mesh filename="package://robot_description/meshes/omnipicker_gripper/narrow1_Link.STL" />
      </geometry>
    </collision>
  </link>

  <joint name="right_hand_narrow1_joint" type="revolute">
    <origin xyz="0 -0.0195 0.0565" rpy="-2.9951 -1.5708 -0.15964" />
    <parent link="right_gripper_base" />
    <child link="right_hand_narrow1_Link" />
    <axis xyz="0 0 -1" />
    <limit lower="-3.14" upper="3.14" effort="5" velocity="3.14" />
  </joint>

  <link name="right_hand_narrow2_Link">
    <inertial>
      <origin xyz="0.0088027 -0.007035 1.6424E-05" rpy="0 0 0" />
      <mass value="0.0040132" />
      <inertia ixx="1.0307E-07" ixy="5.7851E-08" ixz="9.5801E-11" iyy="1.1385E-07" iyz="-2.81E-11" izz="1.7009E-07" />
    </inertial>
    <visual>
      <origin xyz="0 0 0" rpy="0 0 0" />
      <geometry>
        <mesh filename="package://robot_description/meshes/omnipicker_gripper/narrow2_Link.STL" />
      </geometry>
      <material name="">
        <color rgba="0.75294 0.75294 0.75294 1" />
      </material>
    </visual>
    <collision>
      <origin xyz="0 0 0" rpy="0 0 0" />
      <geometry>
        <mesh filename="package://robot_description/meshes/omnipicker_gripper/narrow2_Link.STL" />
      </geometry>
    </collision>
  </link>

  <joint name="right_hand_narrow2_joint" type="revolute">
    <origin xyz="0.030852 0.018551 0" rpy="0 0 0" />
    <parent link="right_hand_narrow1_Link" />
    <child link="right_hand_narrow2_Link" />
    <axis xyz="0 0 -1" />
    <limit lower="-3.14" upper="3.14" effort="5" velocity="3.14" />
  </joint>

  <link name="right_hand_narrow3_Link">
    <inertial>
      <origin xyz="0.012508 -0.0079729 9.4339E-05" rpy="0 0 0" />
      <mass value="0.018029" />
      <inertia ixx="1.1403E-06" ixy="5.5159E-07" ixz="-4.0096E-13" iyy="2.5704E-06" iyz="1.0951E-12" izz="2.3252E-06" />
    </inertial>
    <visual>
      <origin xyz="0 0 0" rpy="0 0 0" />
      <geometry>
        <mesh filename="package://robot_description/meshes/omnipicker_gripper/narrow3_Link.STL" />
      </geometry>
      <material name="">
        <color rgba="0.75294 0.75294 0.75294 1" />
      </material>
    </visual>
    <collision>
      <origin xyz="0 0 0" rpy="0 0 0" />
      <geometry>
        <mesh filename="package://robot_description/meshes/omnipicker_gripper/narrow3_Link.STL" />
      </geometry>
    </collision>
  </link>

  <joint name="right_hand_narrow3_joint" type="revolute">
    <origin xyz="0.018118 -0.01574 0" rpy="0 0 0" />
    <parent link="right_hand_narrow2_Link" />
    <child link="right_hand_narrow3_Link" />
    <axis xyz="0 0 -1" />
    <limit lower="-3.14" upper="3.14" effort="5" velocity="3.14" />
  </joint>

  <link name="right_hand_narrow4_Link" />

  <joint name="right_hand_narrow4_joint" type="fixed">
    <origin xyz="0 -0.0104 0" rpy="0 0 0" />
    <parent link="right_hand_narrow3_Link" />
    <child link="right_hand_narrow4_Link" />
    <axis xyz="0 0 1" />
    <limit lower="-3.14" upper="3.14" effort="5" velocity="3.14" />
  </joint>

  <link name="right_hand_narrow_loop_Link">
    <inertial>
      <origin xyz="0.014869 -0.0036066 0.00029307" rpy="0 0 0" />
      <mass value="0.022591" />
      <inertia ixx="4.3916E-06" ixy="1.114E-07" ixz="-4.9655E-12" iyy="4.737E-06" iyz="1.7121E-11" izz="6.0445E-07" />
    </inertial>
    <visual>
      <origin xyz="0 0 0" rpy="0 0 0" />
      <geometry>
        <mesh filename="package://robot_description/meshes/omnipicker_gripper/narrow_loop_Link.STL" />
      </geometry>
      <material name="">
        <color rgba="0.75294 0.75294 0.75294 1" />
      </material>
    </visual>
    <collision>
      <origin xyz="0 0 0" rpy="0 0 0" />
      <geometry>
        <mesh filename="package://robot_description/meshes/omnipicker_gripper/narrow_loop_Link.STL" />
      </geometry>
    </collision>
  </link>

  <joint name="right_hand_narrow_loop_joint" type="revolute">
    <origin xyz="0 -0.021633 0.07387" rpy="-2.9951 -1.5708 -0.15964" />
    <parent link="right_gripper_base" />
    <child link="right_hand_narrow_loop_Link" />
    <axis xyz="0 0 -1" />
    <limit lower="-3.14" upper="3.14" effort="5" velocity="3.14" />
  </joint>

  <link name="right_hand_wide1_Link">
    <inertial>
      <origin xyz="0.0095051 -0.0068479 6.8268E-05" rpy="0 0 0" />
      <mass value="0.025428" />
      <inertia ixx="1.9565E-06" ixy="4.2798E-07" ixz="2.3844E-10" iyy="2.3928E-06" iyz="-1.4454E-10" izz="1.5501E-06" />
    </inertial>
    <visual>
      <origin xyz="0 0 0" rpy="0 0 0" />
      <geometry>
        <mesh filename="package://robot_description/meshes/omnipicker_gripper/wide1_Link.STL" />
      </geometry>
      <material name="">
        <color rgba="0.75294 0.75294 0.75294 1" />
      </material>
    </visual>
    <collision>
      <origin xyz="0 0 0" rpy="0 0 0" />
      <geometry>
        <mesh filename="package://robot_description/meshes/omnipicker_gripper/wide1_Link.STL" />
      </geometry>
    </collision>
  </link>

  <joint name="right_hand_wide1_joint" type="revolute">
    <origin xyz="0 0.0195 0.0565" rpy="-2.9951 -1.5708 -0.15964" />
    <parent link="right_gripper_base" />
    <child link="right_hand_wide1_Link" />
    <axis xyz="0 0 -1" />
    <limit lower="-3.14" upper="3.14" effort="5" velocity="3.14" />
  </joint>

  <link name="right_hand_wide2_Link">
    <inertial>
      <origin xyz="0.0088027 0.007035 -1.6424E-05" rpy="0 0 0" />
      <mass value="0.0040132" />
      <inertia ixx="1.0307E-07" ixy="-5.7851E-08" ixz="-9.58E-11" iyy="1.1385E-07" iyz="-2.81E-11" izz="1.7009E-07" />
    </inertial>
    <visual>
      <origin xyz="0 0 0" rpy="0 0 0" />
      <geometry>
        <mesh filename="package://robot_description/meshes/omnipicker_gripper/wide2_Link.STL" />
      </geometry>
      <material name="">
        <color rgba="0.75294 0.75294 0.75294 1" />
      </material>
    </visual>
    <collision>
      <origin xyz="0 0 0" rpy="0 0 0" />
      <geometry>
        <mesh filename="package://robot_description/meshes/omnipicker_gripper/wide2_Link.STL" />
      </geometry>
    </collision>
  </link>

  <joint name="right_hand_wide2_joint" type="revolute">
    <origin xyz="0.030852 -0.018551 0" rpy="0 0 0" />
    <parent link="right_hand_wide1_Link" />
    <child link="right_hand_wide2_Link" />
    <axis xyz="0 0 -1" />
    <limit lower="-3.14" upper="3.14" effort="5" velocity="3.14" />
  </joint>

  <link name="right_hand_wide3_Link">
    <inertial>
      <origin xyz="0.016206 0.0094593 4.7668E-05" rpy="0 0 0" />
      <mass value="0.035835" />
      <inertia ixx="8.5056E-06" ixy="-1.1363E-06" ixz="-4.2908E-11" iyy="1.1235E-05" iyz="-2.9251E-11" izz="4.6309E-06" />
    </inertial>
    <visual>
      <origin xyz="0 0 0" rpy="0 0 0" />
      <geometry>
        <mesh filename="package://robot_description/meshes/omnipicker_gripper/wide3_Link.STL" />
      </geometry>
      <material name="">
        <color rgba="0.75294 0.75294 0.75294 1" />
      </material>
    </visual>
    <collision>
      <origin xyz="0 0 0" rpy="0 0 0" />
      <geometry>
        <mesh filename="package://robot_description/meshes/omnipicker_gripper/wide3_Link.STL" />
      </geometry>
    </collision>
  </link>

  <joint name="right_hand_wide3_joint" type="revolute">
    <origin xyz="0.018118 0.01574 0" rpy="0 0 0" />
    <parent link="right_hand_wide2_Link" />
    <child link="right_hand_wide3_Link" />
    <axis xyz="0 0 -1" />
    <limit lower="-3.14" upper="3.14" effort="5" velocity="3.14" />
  </joint>

  <link name="right_hand_wide4_Link" />

  <joint name="right_hand_wide4_joint" type="fixed">
    <origin xyz="0 0.0104 0" rpy="0 0 0" />
    <parent link="right_hand_wide3_Link" />
    <child link="right_hand_wide4_Link" />
    <axis xyz="0 0 1" />
    <limit lower="-3.14" upper="3.14" effort="5" velocity="3.14" />
  </joint>

  <link name="right_hand_wide_loop_Link">
    <inertial>
      <origin xyz="0.016268 0.0040555 0.00030323" rpy="0 0 0" />
      <mass value="0.025142" />
      <inertia ixx="5.887E-06" ixy="-1.1234E-07" ixz="2.1954E-11" iyy="6.236E-06" iyz="-9.473E-12" izz="6.2389E-07" />
    </inertial>
    <visual>
      <origin xyz="0 0 0" rpy="0 0 0" />
      <geometry>
        <mesh filename="package://robot_description/meshes/omnipicker_gripper/wide_loop_Link.STL" />
      </geometry>
      <material name="">
        <color rgba="0.75294 0.75294 0.75294 1" />
      </material>
    </visual>
    <collision>
      <origin xyz="0 0 0" rpy="0 0 0" />
      <geometry>
        <mesh filename="package://robot_description/meshes/omnipicker_gripper/wide_loop_Link.STL" />
      </geometry>
    </collision>
  </link>

  <joint name="right_hand_wide_loop_joint" type="revolute">
    <origin xyz="0 0.021633 0.07387" rpy="-2.9951 -1.5708 -0.15964" />
    <parent link="right_gripper_base" />
    <child link="right_hand_wide_loop_Link" />
    <axis xyz="0 0 -1" />
    <limit lower="-3.14" upper="3.14" effort="5" velocity="3.14" />
  </joint>
</robot>
