<?xml version="1.0"?>
<robot name="arm620" xmlns:xacro="http://www.ros.org/wiki/xacro">

  <link name="base_link">
    <visual>
      <origin xyz="0 0 0" rpy="0 0 0" />
      <geometry>
        <mesh filename="file://$(find robot_description)/arm620/meshes/arm620/base_link.STL" />
      </geometry>
      <material name="base_link_mat">
        <color rgba="1.00000000 1.00000000 1.00000000 1.00000000"/>
      </material>
    </visual>
    <collision>
      <origin xyz="0 0 0" rpy="0 0 0" />
      <geometry>
        <mesh filename="file://$(find robot_description)/arm620/meshes/arm620/base_link.STL" />
      </geometry>
    </collision>
    <inertial>
      <origin xyz="-0.0000349 0 0.041738" rpy="0 0 0" />
      <mass value="1.235" />
      <inertia ixx="0.000693" ixy="0" ixz="-0.0000008" iyy="0.0006922" iyz="0" izz="0.0005921" />
    </inertial>
  </link>

  <link name="Link1">
    <visual>
      <origin xyz="0 0 0" rpy="0 0 0" />
      <geometry>
        <mesh filename="file://$(find robot_description)/arm620/meshes/arm620/Link1.STL" />
      </geometry>
      <material name="Link1_mat">
        <color rgba="1.00000000 1.00000000 1.00000000 1.00000000"/>
      </material>
    </visual>
    <collision>
      <origin xyz="0 0 0" rpy="0 0 0" />
      <geometry>
        <mesh filename="file://$(find robot_description)/arm620/meshes/arm620/Link1.STL" />
      </geometry>
    </collision>
    <inertial>
      <origin xyz="0.0083082 -0.0000009 0.066279" rpy="0 0 0" />
      <mass value="1.0225" />
      <inertia ixx="0.0003347" ixy="0" ixz="-0.000007" iyy="0.0002898" iyz="0" izz="0.0002636" />
    </inertial>
  </link>

  <link name="Link2">
    <visual>
      <origin xyz="0 0 0" rpy="0 0 0" />
      <geometry>
        <mesh filename="file://$(find robot_description)/arm620/meshes/arm620/Link2.STL" />
      </geometry>
      <material name="Link2_mat">
        <color rgba="1.00000000 1.00000000 1.00000000 1.00000000"/>
      </material>
    </visual>
    <collision>
      <origin xyz="0 0 0" rpy="0 0 0" />
      <geometry>
        <mesh filename="file://$(find robot_description)/arm620/meshes/arm620/Link2.STL" />
      </geometry>
    </collision>
    <inertial>
      <origin xyz="0.0000016 0.19554 -0.0019139" rpy="0 0 0" />
      <mass value="1.925" />
      <inertia ixx="0.0092613" ixy="0" ixz="0" iyy="0.0007553" iyz="-0.0000155" izz="0.0090845" />
    </inertial>
  </link>

  <link name="Link3">
    <visual>
      <origin xyz="0 0 0" rpy="0 0 0" />
      <geometry>
        <mesh filename="file://$(find robot_description)/arm620/meshes/arm620/Link3.STL" />
      </geometry>
      <material name="Link3_mat">
        <color rgba="1.00000000 1.00000000 1.00000000 1.00000000"/>
      </material>
    </visual>
    <collision>
      <origin xyz="0 0 0" rpy="0 0 0" />
      <geometry>
        <mesh filename="file://$(find robot_description)/arm620/meshes/arm620/Link3.STL" />
      </geometry>
    </collision>
    <inertial>
      <origin xyz="0.0000183 -0.073691 0.010704" rpy="0 0 0" />
      <mass value="0.73" />
      <inertia ixx="0.0005932" ixy="0.0000001" ixz="0" iyy="0.0001556" iyz="-0.0001132" izz="0.0005538" />
    </inertial>
  </link>

  <link name="Link4">
    <visual>
      <origin xyz="0 0 0" rpy="0 0 0" />
      <geometry>
        <mesh filename="file://$(find robot_description)/arm620/meshes/arm620/Link4.STL" />
      </geometry>
      <material name="Link4_mat">
        <color rgba="1.00000000 1.00000000 1.00000000 1.00000000"/>
      </material>
    </visual>
    <collision>
      <origin xyz="0 0 0" rpy="0 0 0" />
      <geometry>
        <mesh filename="file://$(find robot_description)/arm620/meshes/arm620/Link4.STL" />
      </geometry>
    </collision>
    <inertial>
      <origin xyz="0.0059454 0.0000251 0.051809" rpy="0 0 0" />
      <mass value="0.5174" />
      <inertia ixx="0.0001034" ixy="0" ixz="-0.0000079" iyy="0.0001193" iyz="0" izz="0.0000856" />
    </inertial>
  </link>

  <link name="Link5">
    <visual>
      <origin xyz="0 0 0" rpy="0 0 0" />
      <geometry>
        <mesh filename="file://$(find robot_description)/arm620/meshes/arm620/Link5.STL" />
      </geometry>
      <material name="Link5_mat">
        <color rgba="1.00000000 1.00000000 1.00000000 1.00000000"/>
      </material>
    </visual>
    <collision>
      <origin xyz="0 0 0" rpy="0 0 0" />
      <geometry>
        <mesh filename="file://$(find robot_description)/arm620/meshes/arm620/Link5.STL" />
      </geometry>
    </collision>
    <inertial>
      <origin xyz="0.0095168 0.061153 0.0000101" rpy="0 0 0" />
      <mass value="0.7233" />
      <inertia ixx="0.0001359" ixy="0.0000391" ixz="0" iyy="0.0001006" iyz="-0.0000001" izz="0.0001594" />
    </inertial>
  </link>

  <link name="Link6">
    <visual>
      <origin xyz="0 0 0" rpy="0 0 0" />
      <geometry>
        <mesh filename="file://$(find robot_description)/arm620/meshes/arm620/Link6.STL" />
      </geometry>
      <material name="Link6_mat">
        <color rgba="1.00000000 1.00000000 1.00000000 1.00000000"/>
      </material>
    </visual>
    <collision>
      <origin xyz="0 0 0" rpy="0 0 0" />
      <geometry>
        <mesh filename="file://$(find robot_description)/arm620/meshes/arm620/Link6.STL" />
      </geometry>
    </collision>
    <inertial>
      <origin xyz="-0.0023023 0.0016027 0.010682" rpy="0 0 0" />
      <mass value="0.0953" />
      <inertia ixx="0.0000132" ixy="-0.0000001" ixz="0.0000002" iyy="0.0000134" iyz="-0.0000002" izz="0.0000246" />
    </inertial>
  </link>

  <link name="world">
  </link>

  <joint name="joint1" type="revolute">
    <parent link="base_link" />
    <child link="Link1" />
    <origin xyz="0 0 0.084" rpy="0 0 0" />
    <axis xyz="0 0 1" />
    <limit lower="-2.967" upper="2.967" effort="0" velocity="0" />
  </joint>

  <joint name="joint2" type="revolute">
    <parent link="Link1" />
    <child link="Link2" />
    <origin xyz="0 0 0.068718" rpy="1.5708 0 -1.5708" />
    <axis xyz="0 0 -1" />
    <limit lower="-1.5708" upper="1.5708" effort="0" velocity="0" />
  </joint>

  <joint name="joint3" type="revolute">
    <parent link="Link2" />
    <child link="Link3" />
    <origin xyz="0 0.30025 0" rpy="-3.1416 0 0" />
    <axis xyz="0 0 1" />
    <limit lower="-1.5708" upper="1.5708" effort="0" velocity="0" />
  </joint>

  <joint name="joint4" type="revolute">
    <parent link="Link3" />
    <child link="Link4" />
    <origin xyz="0 -0.15558 0.000035" rpy="1.5708 -1.5708 0" />
    <axis xyz="0 0 1" />
    <limit lower="-2.967" upper="2.967" effort="0" velocity="0" />
  </joint>

  <joint name="joint5" type="revolute">
    <parent link="Link4" />
    <child link="Link5" />
    <origin xyz="-0.000035 0.0000154 0.064223" rpy="1.5708 0 0" />
    <axis xyz="1 0 0" />
    <limit lower="-1.5708" upper="1.5708" effort="0" velocity="0" />
  </joint>

  <joint name="joint6" type="revolute">
    <parent link="Link5" />
    <child link="Link6" />
    <origin xyz="-0.0004752 0.095552 0" rpy="-1.5709 0 0" />
    <axis xyz="0 0 1" />
    <limit lower="-2.967" upper="2.967" effort="0" velocity="0" />
  </joint>

  <joint name="base_joint" type="fixed">
    <parent link="world" />
    <child link="base_link" />
    <origin xyz="0 0 0" rpy="0 0 0" />
  </joint>


  <xacro:arg name="ros_profile" default="ros2" />
  <xacro:arg name="ros_hardware_interface" default="effort" />

  <xacro:if value="${xacro.arg('ros_profile') == 'ros1' and xacro.arg('ros_hardware_interface') == 'effort'}">
      <transmission name="joint1_trans">
        <type>transmission_interface/SimpleTransmission</type>
        <joint name="joint1">
          <hardwareInterface>hardware_interface/EffortJointInterface</hardwareInterface>
        </joint>
        <actuator name="joint1_motor">
          <hardwareInterface>hardware_interface/EffortJointInterface</hardwareInterface>
          <mechanicalReduction>1</mechanicalReduction>
        </actuator>
      </transmission>

      <transmission name="joint2_trans">
        <type>transmission_interface/SimpleTransmission</type>
        <joint name="joint2">
          <hardwareInterface>hardware_interface/EffortJointInterface</hardwareInterface>
        </joint>
        <actuator name="joint2_motor">
          <hardwareInterface>hardware_interface/EffortJointInterface</hardwareInterface>
          <mechanicalReduction>1</mechanicalReduction>
        </actuator>
      </transmission>

      <transmission name="joint3_trans">
        <type>transmission_interface/SimpleTransmission</type>
        <joint name="joint3">
          <hardwareInterface>hardware_interface/EffortJointInterface</hardwareInterface>
        </joint>
        <actuator name="joint3_motor">
          <hardwareInterface>hardware_interface/EffortJointInterface</hardwareInterface>
          <mechanicalReduction>1</mechanicalReduction>
        </actuator>
      </transmission>

      <transmission name="joint4_trans">
        <type>transmission_interface/SimpleTransmission</type>
        <joint name="joint4">
          <hardwareInterface>hardware_interface/EffortJointInterface</hardwareInterface>
        </joint>
        <actuator name="joint4_motor">
          <hardwareInterface>hardware_interface/EffortJointInterface</hardwareInterface>
          <mechanicalReduction>1</mechanicalReduction>
        </actuator>
      </transmission>

      <transmission name="joint5_trans">
        <type>transmission_interface/SimpleTransmission</type>
        <joint name="joint5">
          <hardwareInterface>hardware_interface/EffortJointInterface</hardwareInterface>
        </joint>
        <actuator name="joint5_motor">
          <hardwareInterface>hardware_interface/EffortJointInterface</hardwareInterface>
          <mechanicalReduction>1</mechanicalReduction>
        </actuator>
      </transmission>

      <transmission name="joint6_trans">
        <type>transmission_interface/SimpleTransmission</type>
        <joint name="joint6">
          <hardwareInterface>hardware_interface/EffortJointInterface</hardwareInterface>
        </joint>
        <actuator name="joint6_motor">
          <hardwareInterface>hardware_interface/EffortJointInterface</hardwareInterface>
          <mechanicalReduction>1</mechanicalReduction>
        </actuator>
      </transmission>

      <gazebo>
        <plugin name="gazebo_ros_control" filename="libgazebo_ros_control.so">
          <robotNamespace>/arm620_gazebo</robotNamespace>
          <robotSimType>gazebo_ros_control/DefaultRobotHWSim</robotSimType>
        </plugin>
      </gazebo>

  </xacro:if>

  <xacro:if value="${xacro.arg('ros_profile') == 'ros1' and xacro.arg('ros_hardware_interface') == 'position'}">
      <transmission name="joint1_trans">
        <type>transmission_interface/SimpleTransmission</type>
        <joint name="joint1">
          <hardwareInterface>hardware_interface/PositionJointInterface</hardwareInterface>
        </joint>
        <actuator name="joint1_motor">
          <hardwareInterface>hardware_interface/PositionJointInterface</hardwareInterface>
          <mechanicalReduction>1</mechanicalReduction>
        </actuator>
      </transmission>

      <transmission name="joint2_trans">
        <type>transmission_interface/SimpleTransmission</type>
        <joint name="joint2">
          <hardwareInterface>hardware_interface/PositionJointInterface</hardwareInterface>
        </joint>
        <actuator name="joint2_motor">
          <hardwareInterface>hardware_interface/PositionJointInterface</hardwareInterface>
          <mechanicalReduction>1</mechanicalReduction>
        </actuator>
      </transmission>

      <transmission name="joint3_trans">
        <type>transmission_interface/SimpleTransmission</type>
        <joint name="joint3">
          <hardwareInterface>hardware_interface/PositionJointInterface</hardwareInterface>
        </joint>
        <actuator name="joint3_motor">
          <hardwareInterface>hardware_interface/PositionJointInterface</hardwareInterface>
          <mechanicalReduction>1</mechanicalReduction>
        </actuator>
      </transmission>

      <transmission name="joint4_trans">
        <type>transmission_interface/SimpleTransmission</type>
        <joint name="joint4">
          <hardwareInterface>hardware_interface/PositionJointInterface</hardwareInterface>
        </joint>
        <actuator name="joint4_motor">
          <hardwareInterface>hardware_interface/PositionJointInterface</hardwareInterface>
          <mechanicalReduction>1</mechanicalReduction>
        </actuator>
      </transmission>

      <transmission name="joint5_trans">
        <type>transmission_interface/SimpleTransmission</type>
        <joint name="joint5">
          <hardwareInterface>hardware_interface/PositionJointInterface</hardwareInterface>
        </joint>
        <actuator name="joint5_motor">
          <hardwareInterface>hardware_interface/PositionJointInterface</hardwareInterface>
          <mechanicalReduction>1</mechanicalReduction>
        </actuator>
      </transmission>

      <transmission name="joint6_trans">
        <type>transmission_interface/SimpleTransmission</type>
        <joint name="joint6">
          <hardwareInterface>hardware_interface/PositionJointInterface</hardwareInterface>
        </joint>
        <actuator name="joint6_motor">
          <hardwareInterface>hardware_interface/PositionJointInterface</hardwareInterface>
          <mechanicalReduction>1</mechanicalReduction>
        </actuator>
      </transmission>

      <gazebo>
        <plugin name="gazebo_ros_control" filename="libgazebo_ros_control.so">
          <robotNamespace>/arm620_gazebo</robotNamespace>
          <robotSimType>gazebo_ros_control/DefaultRobotHWSim</robotSimType>
        </plugin>
      </gazebo>

  </xacro:if>

  <xacro:if value="${xacro.arg('ros_profile') == 'ros1' and xacro.arg('ros_hardware_interface') == 'velocity'}">
      <transmission name="joint1_trans">
        <type>transmission_interface/SimpleTransmission</type>
        <joint name="joint1">
          <hardwareInterface>hardware_interface/VelocityJointInterface</hardwareInterface>
        </joint>
        <actuator name="joint1_motor">
          <hardwareInterface>hardware_interface/VelocityJointInterface</hardwareInterface>
          <mechanicalReduction>1</mechanicalReduction>
        </actuator>
      </transmission>

      <transmission name="joint2_trans">
        <type>transmission_interface/SimpleTransmission</type>
        <joint name="joint2">
          <hardwareInterface>hardware_interface/VelocityJointInterface</hardwareInterface>
        </joint>
        <actuator name="joint2_motor">
          <hardwareInterface>hardware_interface/VelocityJointInterface</hardwareInterface>
          <mechanicalReduction>1</mechanicalReduction>
        </actuator>
      </transmission>

      <transmission name="joint3_trans">
        <type>transmission_interface/SimpleTransmission</type>
        <joint name="joint3">
          <hardwareInterface>hardware_interface/VelocityJointInterface</hardwareInterface>
        </joint>
        <actuator name="joint3_motor">
          <hardwareInterface>hardware_interface/VelocityJointInterface</hardwareInterface>
          <mechanicalReduction>1</mechanicalReduction>
        </actuator>
      </transmission>

      <transmission name="joint4_trans">
        <type>transmission_interface/SimpleTransmission</type>
        <joint name="joint4">
          <hardwareInterface>hardware_interface/VelocityJointInterface</hardwareInterface>
        </joint>
        <actuator name="joint4_motor">
          <hardwareInterface>hardware_interface/VelocityJointInterface</hardwareInterface>
          <mechanicalReduction>1</mechanicalReduction>
        </actuator>
      </transmission>

      <transmission name="joint5_trans">
        <type>transmission_interface/SimpleTransmission</type>
        <joint name="joint5">
          <hardwareInterface>hardware_interface/VelocityJointInterface</hardwareInterface>
        </joint>
        <actuator name="joint5_motor">
          <hardwareInterface>hardware_interface/VelocityJointInterface</hardwareInterface>
          <mechanicalReduction>1</mechanicalReduction>
        </actuator>
      </transmission>

      <transmission name="joint6_trans">
        <type>transmission_interface/SimpleTransmission</type>
        <joint name="joint6">
          <hardwareInterface>hardware_interface/VelocityJointInterface</hardwareInterface>
        </joint>
        <actuator name="joint6_motor">
          <hardwareInterface>hardware_interface/VelocityJointInterface</hardwareInterface>
          <mechanicalReduction>1</mechanicalReduction>
        </actuator>
      </transmission>

      <gazebo>
        <plugin name="gazebo_ros_control" filename="libgazebo_ros_control.so">
          <robotNamespace>/arm620_gazebo</robotNamespace>
          <robotSimType>gazebo_ros_control/DefaultRobotHWSim</robotSimType>
        </plugin>
      </gazebo>

  </xacro:if>

  <xacro:if value="${xacro.arg('ros_profile') == 'ros2' and xacro.arg('ros_hardware_interface') == 'effort'}">
      <ros2_control name="arm620" type="system">
        <hardware>
          <plugin>gazebo_ros2_control/GazeboSystem</plugin>
        </hardware>
        <joint name="joint1">
          <command_interface name="effort"/>
          <state_interface name="position"/>
          <state_interface name="velocity"/>
          <state_interface name="effort"/>
        </joint>
        <joint name="joint2">
          <command_interface name="effort"/>
          <state_interface name="position"/>
          <state_interface name="velocity"/>
          <state_interface name="effort"/>
        </joint>
        <joint name="joint3">
          <command_interface name="effort"/>
          <state_interface name="position"/>
          <state_interface name="velocity"/>
          <state_interface name="effort"/>
        </joint>
        <joint name="joint4">
          <command_interface name="effort"/>
          <state_interface name="position"/>
          <state_interface name="velocity"/>
          <state_interface name="effort"/>
        </joint>
        <joint name="joint5">
          <command_interface name="effort"/>
          <state_interface name="position"/>
          <state_interface name="velocity"/>
          <state_interface name="effort"/>
        </joint>
        <joint name="joint6">
          <command_interface name="effort"/>
          <state_interface name="position"/>
          <state_interface name="velocity"/>
          <state_interface name="effort"/>
        </joint>
      </ros2_control>

      <gazebo>
        <plugin name="gazebo_ros2_control" filename="libgazebo_ros2_control.so">
          <robot_param>robot_description</robot_param>
          <robot_param_node>robot_state_publisher</robot_param_node>
        </plugin>
      </gazebo>

  </xacro:if>

  <xacro:if value="${xacro.arg('ros_profile') == 'ros2' and xacro.arg('ros_hardware_interface') == 'position'}">
      <ros2_control name="arm620" type="system">
        <hardware>
          <plugin>gazebo_ros2_control/GazeboSystem</plugin>
        </hardware>
        <joint name="joint1">
          <command_interface name="position"/>
          <state_interface name="position"/>
          <state_interface name="velocity"/>
        </joint>
        <joint name="joint2">
          <command_interface name="position"/>
          <state_interface name="position"/>
          <state_interface name="velocity"/>
        </joint>
        <joint name="joint3">
          <command_interface name="position"/>
          <state_interface name="position"/>
          <state_interface name="velocity"/>
        </joint>
        <joint name="joint4">
          <command_interface name="position"/>
          <state_interface name="position"/>
          <state_interface name="velocity"/>
        </joint>
        <joint name="joint5">
          <command_interface name="position"/>
          <state_interface name="position"/>
          <state_interface name="velocity"/>
        </joint>
        <joint name="joint6">
          <command_interface name="position"/>
          <state_interface name="position"/>
          <state_interface name="velocity"/>
        </joint>
      </ros2_control>

      <gazebo>
        <plugin name="gazebo_ros2_control" filename="libgazebo_ros2_control.so">
          <robot_param>robot_description</robot_param>
          <robot_param_node>robot_state_publisher</robot_param_node>
        </plugin>
      </gazebo>

  </xacro:if>

  <xacro:if value="${xacro.arg('ros_profile') == 'ros2' and xacro.arg('ros_hardware_interface') == 'velocity'}">
      <ros2_control name="arm620" type="system">
        <hardware>
          <plugin>gazebo_ros2_control/GazeboSystem</plugin>
        </hardware>
        <joint name="joint1">
          <command_interface name="velocity"/>
          <state_interface name="position"/>
          <state_interface name="velocity"/>
        </joint>
        <joint name="joint2">
          <command_interface name="velocity"/>
          <state_interface name="position"/>
          <state_interface name="velocity"/>
        </joint>
        <joint name="joint3">
          <command_interface name="velocity"/>
          <state_interface name="position"/>
          <state_interface name="velocity"/>
        </joint>
        <joint name="joint4">
          <command_interface name="velocity"/>
          <state_interface name="position"/>
          <state_interface name="velocity"/>
        </joint>
        <joint name="joint5">
          <command_interface name="velocity"/>
          <state_interface name="position"/>
          <state_interface name="velocity"/>
        </joint>
        <joint name="joint6">
          <command_interface name="velocity"/>
          <state_interface name="position"/>
          <state_interface name="velocity"/>
        </joint>
      </ros2_control>

      <gazebo>
        <plugin name="gazebo_ros2_control" filename="libgazebo_ros2_control.so">
          <robot_param>robot_description</robot_param>
          <robot_param_node>robot_state_publisher</robot_param_node>
        </plugin>
      </gazebo>

  </xacro:if>
</robot>
